Workbook

Sheet README
A1: ED-018-2026-06 ACCESS OPTIONS MODEL REV B
A2: Companion to report ED-018-2026-02 Rev B, 26 August 2026. Commercial in confidence.
A4: What changed at Rev B
A5: Scenarios sheet added: the marine base with and without, at current and serviced trade productivity, with live formulas.
A6: BaseMenu sheet added: concepts C0 to C6, each with its own cycle and availability assumption.
A7: Levers sheet rebuilt per option so every package reconciles from the lines above it.
A8: Inputs sheet extended with the written marine rate references of 24 August 2026.
A9: Sensitivity relabelled: the reported case is the marine review upper band; the old model base tag removed.
A10: Programme sheet extended with Option 1, zone phased and compressed day finish dates.
A12: Reading order: Inputs, Options, Scenarios, BaseMenu, Levers, Sensitivity, Programme, NoBase, RateCard.
A13: Every figure quoted in the report traces to one of these sheets.
A15: How to read this model, for a first time reader
... A20: Every headline figure in the report traces to a cell here, and the Independent Checks block at the foot of Scenarios shows each one re derived outside the workbook.

Sheet Dashboard
A1: DASHBOARD all series formula fed from Scenarios and Sensitivity | L1: PURPOSE: the headline charts, formula fed; nothing here is typed independently of the sheets.
A3: No marine base | B3: =Scenarios!H5
A4: Barge whole campaign, conservative | B4: =Scenarios!H6
A5: Barge, serviced productivity 6.5 | B5: =Scenarios!H7
A6: Barge, serviced optimistic 6.0 | B6: =Scenarios!H8
A7: Serviced, fleet trimmed to 7 | B7: 15.41
A8: Barge Zone 3 season one only | B8: 14.68
A9: Moored spud whole campaign | B9: 12.26
A10: Self sufficient fronts added | B10: 18.59
A13: Fleet by availability case
A14: Reported | B14: 8 | C14: 5 | D14: 6
A15: Mid | B15: 9 | C15: 6 | D15: 7
A16: Pessimistic | B16: 10 | C16: 6 | D16: 7
A17: No library | B17: 11 | C17: 8 | D17: 8
A21: Cumulative delivery to 227 (weeks from May 2027)
A22: 0 | B22: 0 | C22: 0
A23: 10 | B23: 47 | C23: 3.6
A24: 20 | B24: 94 | C24: 7.2
A25: 26 | B25: 118 | C25: 9.4
A26: 52 | B26: 118 | C26: 18.7
A27: 62 | B27: 165 | C27: 22.3
A28: 72 | B28: 212 | C28: 25.9
A29: 78 | B29: 227 | C29: 28.1
A30: 86 | B30: 227 | C30: 31
A33: Cost build Opt1 ($M): kit 2.23, base 3.40, labour 4.72, fixed 2.48, contingency 3.21
A34: Kit | B34: 2.23
A35: Base | B35: 3.4
A36: Labour | B36: 4.72
A37: Fixed | B37: 2.48
A38: Contingency | B38: 3.21

Sheet Options
A1: Option 1 base case against Option 2 optimised, night shift on trades | L1: PURPOSE: the two working patterns side by side, cycle, fleet and cost, at the carried availabilities.
A2: Both options use the same trade content, the same crews and the same rates. Only the access arrangement differs.
B4: OPTION 1 Base case Day shift only, as Draft A | C4: OPTION 2 Optimised Trades day & night, platforms move in daylight only | D4: Note
A5: THE CYCLE
A6: Trade shifts worked per calendar day | B6: 1 | C6: =1+Inputs!$B$15 | D6: Option 2 adds a night shift on the trades only, derated for night productivity
A7: Effective access days per bent | B7: =Inputs!$B$9/Inputs!$B$13 | C7: =Inputs!$B$9/Inputs!$B$13 | D7: Moves are daylight only in both options. Platform is floating during a move, so it carries the floating availability
A8: Effective trade days per bent | B8: =(Inputs!$B$10/B6)/Inputs!$B$14 | C8: =(Inputs!$B$10/C6)/Inputs!$B$14 | D8: Once lifted and transferred onto positive ties the platform is a fixed suspended platform, so trade work carries the fixed availability
A9: Approval hold days | B9: =Inputs!$B$11*(1-Inputs!$B$12) | C9: =Inputs!$B$11*(1-Inputs!$B$12) | D9: Removed in both options if the repair library is agreed under contract Appendix J
A10: EFFECTIVE CYCLE, days per bent | B10: =B7+B8+B9 | C10: =C7+C8+C9
A12: THE FLEET
A13: Bents per week, one front | B13: =Inputs!$B$8/B10 | C13: =Inputs!$B$8/C10
A14: Bents per week required | B14: =Inputs!$B$6/Inputs!$B$7 | C14: =Inputs!$B$6/Inputs!$B$7 | D14: 227 bents across the two available seasons
A15: WORK FRONTS REQUIRED | B15: =ROUNDUP(B14/B13,0) | C15: =ROUNDUP(C14/C13,0) | D15: One front = two floating stage halves working one bent
A16: Stage halves in the water | B16: =B15*2 | C16: =C15*2 | D16: Supplier holds five platforms today. The balance is the fleet build, still POA
A17: Chain blocks required | B17: =B15*4 | C17: =C15*4 | D17: Four Kito 2 t per front
A18: Clamp sets rigged (working plus one bent ahead) | B18: =B15*2 | C18: =C15*2
A19: Campaign weeks | B19: =MIN(Inputs!$B$7,Inputs!$B$6/(B15*B13)) | C19: =MIN(Inputs!$B$7,Inputs!$B$6/(C15*C13))
A21: HEADCOUNT
A22: Trade heads on shift (contractor's cost, not ours) | B22: =B15*5 | C22: =C15*5*2 | D22: Five trades per face. Option 2 runs two crews per front. Total trade person-shifts is identical at 227 x 7 x 5 = 7,945
A23: Access crew, day shift | B23: =ROUNDUP(B15*Inputs!$B$16,0) | C23: =ROUNDUP(C15*Inputs!$B$16,0) | D23: Riggers, scaffolders, coxswains. A fleet crew, not a per front crew
A24: Access crew, night shift | B24: 0 | C24: =Inputs!$B$17 | D24: Option 2 only. No moves, no lifting, no man riding at night. Rescue capability and permit control still required
A25: Total on site | B25: =B22+B23+B24 | C25: =C22+C23+C24
A27: ACCESS COST, our scope only
A28: Access kit and support crane | B28: =Inputs!$B$20*B15*B19+Inputs!$B$22*B19 | C28: =Inputs!$B$20*C15*C19+Inputs!$B$22*C19 | D28: Winch sets, pontoons, module, davit per front, plus one support crane for the fleet at the card low band
A29: Marine base, operating | B29: =Inputs!$B$19*7*B19 | C29: =Inputs!$B$19*7*C19 | D29: Largest single line. Manned jack up is the base for service autonomy: air, power, welding, welfare on the water. Spud flat top remains a priced lever with its service continuity risk stated
A30: Access labour | B30: =B23*Inputs!$B$8*B19*Inputs!$B$18+B24*Inputs!$B$8*B19*Inputs!$B$23 | C30: =C23*Inputs!$B$8*C19*Inputs!$B$18+C24*Inputs!$B$8*C19*Inputs!$B$23 | D30: Access crew only. Trade labour stays inside the contractor lump sums and is excluded from this estimate
A31: Fixed access lines | B31: =Inputs!$B$38 | C31: =Inputs!$B$38 | D31: Identical in both options
A32: Subtotal | B32: =SUM(B28:B31) | C32: =SUM(C28:C31)
A33: Contingency | B33: =B32*Inputs!$B$21 | C33: =C32*Inputs!$B$21 | D33: AACE Class 5
A34: ACCESS TOTAL | B34: =B32+B33 | C34: =C32+C33
A35: Access cost per bent | B35: =B34/Inputs!$B$6 | C35: =C34/Inputs!$B$6
A36: Saving of Option 2 against Option 1 | C36: =B34-C34
A38: WHAT ELSE CHANGES
A39: Marine risk exposure | B39: Moves, lifting and man riding in daylight only | C39: Unchanged. No moves, no lifting, no man riding at night. Night work is trade work on a platform already lifted and tied off, accessed from the jetty deck | D39: Option 2 does not add marine risk, it adds hours on a static platform
A40: Rescue over water | B40: Day only | C40: Required at night as well. The one marine duty that does not go away | D40: Cost carried in the night standby crew above
A41: Recoat window | B41: Blast and first coat can fall either side of a night, risking flash rust and rework | C41: Blast runs into first coat across the day and night boundary, inside the window | D41: The incumbent record already shows defects found after blast, reblast and touch up
A42: Fabrication lead time | B42: More halves to build before a March 2027 mobilisation | C42: Fewer halves. This is the largest programme benefit, not the cost saving | D42: Fleet build is still POA in both options
A43: Accommodation, Ingham | B43: Fewer beds | C43: More beds, and two shift patterns to roster | D43: Trade contractor's cost, but STL will ask
A44: Light spill, marine park | B44: Not applicable | C44: GBRMPA question. The encapsulated habitat contains most of it | D44: Raise in the approvals pathway
A46: Before Option 2 goes to STL, verify: (1) that night work is a choice and not a prohibition under the contract, MSQ, the port authority or GBRMPA, since Draft A states it as a site constraint; (2) the night rescue and medevac arrangement; (3) light spill against the marine park conditions; (4) that the coating supplier supports night application.
...

Sheet Inputs
A1: ED-018-2026-06 Access Options Model, Rev A | L1: PURPOSE: every rate and physical assumption used anywhere in this model, with its source or judgement flag beside it. All rates AUD.
A2: Lucinda jetty remediation. Two access options compared on one basis. Access scope only: trade works are held at the contractor's own durations, crews and rates and are not re-priced.
A3: Blue cells are inputs you may change. Yellow cells are unconfirmed with the owner named. Everything else is formula.
A5: Input | B5: Value | C5: Unit | D5: Source and confidence
A6: Priority bents | B6: 227 | C6: ea | D6: Contract Appendix D priority scope. Planning basis pending the STL bent register
A7: Available weeks | B7: 50.4 | C7: wk | D7: Two 26 week seasons less 1.6 ship call weeks
A8: Working days per week | B8: 6 | C8: d | D8: No Sundays, no seventh day
A9: Access (move) shifts per bent | B9: 2 | C9: sh | D9: Supplier stated: move on 1, move off 1
A10: Trade shifts per bent | B10: 7 | C10: sh | D10: Contractor programme, held identical in both options
A11: Approval hold | B11: 3 | C11: d | D11: Contractor programme column
A12: Repair library agreed (1 yes, 0 no) | B12: 1 | C12: flag | D12: STL decision under contract Appendix J; the executed contract itself carried a night work provision
A13: Availability: platform floating, during moves | B13: 0.8 | D13: Marine review upper band. The manned jack up base with a support crane holds move windows; the 2026 trial measures the achieved figure before the fleet order
A14: Availability: platform fixed on positive ties, trade work | B14: 0.9 | D14: Fixed suspended platform, enclosed habitat, night continuity. Upper band of the marine review; trial measured
A15: Night crew productivity vs day | B15: 1 | D15: Parity carried on the evidence of enclosed, lit, fixed platform working; adjust this cell to test a derate at the workshop; HP5 confirms the position
A16: Access crew per front | B16: 1.3333 | C16: heads | D16: 12 heads at 9 fronts: riggers, scaffolders, coxswains. Day shift only
A17: Night standby crew: rescue coxswain and crew, permit officer | B17: 2 | C17: heads | D17: Option 2 only. Required, not optional: crews work over water at night
A18: Access crew head day cost, day shift | B18: 1471.43 | C18: $/d | D18: Contract schedule of rates 4.1.2 scaffolder at 110 for 2027 for five access crew, with coxswain and deckhand from the supplier card where the contract carries no marine role. Ten hour shift plus 350 allowances
A19: Marine base, operating | B19: 10000 | C19: $/d | D19: ABH SeaLift 6 via T Glenister 20 Aug. CONFLICTS with $32,000/month on file
A20: Access kit per front | B20: 5400 | C20: $/front-wk | D20: Basis: winch set 2,500 + pontoons 1,400 + module 1,500
A21: Contingency | B21: 0.25 | D21: AACE Class 5 screening
A22: Support crane, platform moves and recovery | B22: 2600 | C22: $/wk | D22: Card low band, Franna class. One crane serves the fleet; day hire at mobilisation sits in the haulage line
A23: Night standby head day cost | B23: 1877.5 | D23: Coxswain and deckhand blended, plus the 30 percent nightshift uplift from the supplier card note 6.5, ten hour shift plus 350 allowances
A24: Nightshift uplift applied | B24: 0.3 | D24: GGC rate card pricing note 6.5
A25: Clamp and suspension certification, lift plans, man-riding certs | B25: 55500 | D25: Supplier scope, two engineers
A26: Approvals, inductions, VOCs, first-fit PPE, access crew | B26: 27750 | D26: Card 6.1
A27: Blastclad containment skin, $350 x 227 bents | B27: 79450 | D27: Containment is part of the platform
A28: Assemble and proof load each front | B28: 66600 | D28: 3 riggers and leading hand, 1 shift per front
A29: Marine mobilisation, tow in, establish | B29: 148500 | D29: Timing dependent
A30: Kit haulage, 8 semis | B30: 121500 | D30: Crawler POA
A31: Rescue proof and cyclone recovery drill | B31: 55500 | D31: Gate before the fleet grows
A32: Trial bent proven to the Superintendent | B32: 155400 | D32: Calibrates the true cycle
A33: Marine standby through the wet season | B33: 910000 | D33: 26 wk at half rate. TBC line by line
A34: Kit standby through the wet season | B34: 475800 | D34: Electrical and vehicles off site
... A37: Records, MDR, DLP allowance | B37: 18500 | D37: Contract 8.1.0
A38: Subtotal, fixed access lines | B38: =SUM(B25:B37)
A40: Not priced in either option: fleet build or hire (Activity 2.1, POA, five platforms exist), marine hull and P&I insurances, GBRMPA and MSQ permits, port charges, accommodation, escalation from August 2026 money.
A43: CURRENT METHOD ACCESS, contract rates
A44: Scaffold hire, typical pilebent | B44: 88.2 | C44: $/day | D44: Contract schedule of rates 4.2.10, 2027 column
A45: Scaffolder | B45: 110 | C45: $/hr | D45: Contract schedule of rates 4.1.2, 2027 column
A46: Supervisor | B46: 130 | C46: $/hr | D46: Contract schedule of rates 4.1.5, 2027 column
...

Sheet Scenarios
A1: THE MARINE BASE, WITH AND WITHOUT: COST AND PRODUCTIVITY (Option 1, day shift) | L1: PURPOSE: the marine base priced with, without, and deployed different ways; trade shifts per bent is the productivity dial.
A2: Live formulas. Trade shifts per bent is the productivity dial: 7.0 is the current contractor content; the serviced central case is 6.5 with 6.0 as the optimistic bound. Cure, tide and approval waits gain nothing.
A4: Scenario | B4: Trade shifts/bent | C4: Fixed avail | D4: Fronts | E4: Cycle d | F4: Rate /front/wk | G4: Campaign wk | H4: Access $M | I4: Modelled note
A5: Without base: current productivity, wharf serviced | B5: 7 | C5: 0.82 | D5: 9 | E5: =2/0.8+B5/C5 | F5: =6/E5 | G5: =227/(D5*F5) | H5: 12.49 | I5: Ties to the NoBase sheet total $12.49M; services queue on the roadway
A6: With base: tendered content held (conservative, reported) | B6: 7 | C6: 0.9 | D6: 8 | E6: =2/0.8+B6/C6 | F6: =6/E6 | G6: =227/(D6*F6) | H6: =((D6*5400+2600)*G6+10000*7*G6+CEILING(D6*4/3,1)*1471.43*G6*6+2481000)*1.25/1000000 | I6: Finish 11 Oct 2028; the Rev A basis
A7: With base: serviced productivity, central case, fleet held | B7: 6.5 | C7: 0.9 | D7: 8 | E7: =2/0.8+B7/C7 | F7: =6/E7 | G7: =227/(D7*F7) | H7: =((D7*5400+2600)*G7+10000*7*G7+CEILING(D7*4/3,1)*1471.43*G7*6+2481000)*1.25/1000000 | I7: Finish 17 Sep 2028; optimistic bound 6.0 shifts gives $14.64M, 5 Sep
A8: With base: serviced at the optimistic bound, fleet trimmed | B8: 6 | C8: 0.9 | D8: 7 | E8: =2/0.8+B8/C8 | F8: =6/E8 | G8: =227/(D8*F8) | H8: =((D8*5400+2600)*G8+10000*7*G8+CEILING(D8*4/3,1)*1471.43*G8*6+2481000)*1.25/1000000 | I8: Finish 18 Oct 2028; one less front to fabricate
A10: S2a Adverse bound: trades one full shift slower on the stage (measured at the trial) | B10: 8 | C10: 0.9 | D10: 9 | E10: =2/0.8+B10/C10 | F10: =6/E10 | G10: =227/(D10*F10) | H10: =((D10*5400+2600)*G10+10000*7*G10+CEILING(D10*4/3,1)*1471.43*G10*6+2481000)*1.25/1000000 | I10: Finish about 6 Oct 2028; October holds
A11: S2z Reported case at zone seeded availability, season one in Zone 3 | B11: 7 | D11: 9 | E11: =2/Inputs!B82+B11/Inputs!C82 | F11: =6/E11 | G11: =227/(D11*F11) | H11: =((D11*5400+2600)*G11+10000*7*G11+CEILING(D11*4/3,1)*1471.43*G11*6+2481000)*1.25/1000000 | I11: Season one fronts nine at Zone 3 seeds; finish early October; trial collapses the range
A12: RECOMMENDED SCENARIO SWITCH | B12: Zone phased | C12: Conditional recommendation: keep the barge whole campaign if the written day rate lands near $20,000 a week; zone phased if $10,000 a day confirms. Update this cell when the operator letter lands.
A13: OPTION 2 REFERENCES (two trade shifts per calendar day; same formula structure)
A14: With base, serviced 6.0 trade shifts | D14: 5 | E14: 5.83 | F14: 1.029 | G14: 44.1 | H14: 13.25 | I14: Finish 10 Sep 2028
A15: Compressed day pattern, serviced 6.0 | D15: 6 | E15: 6.67 | F15: 0.9 | G15: 42 | H15: 12.92 | I15: Finish late Aug 2028
A17: INDEPENDENT CHECKS, appended at final verification
A18: Every scenario re derived outside the workbook and compared to the formula or static value above. Agreement to the cent at two decimals.
A19: S1 no base 7.0@0.82 9fr | B19: 12.52 | C19: agrees
A20: S2 conservative 7.0@0.90 8fr | B20: 16.04 | C20: agrees
A21: S3 serviced 6.5 8fr | B21: 15.34 | C21: agrees
A22: S3a serviced 6.0 8fr | B22: 14.64 | C22: agrees
A23: S4 trimmed 6.0 7fr | B23: 15.41 | C23: agrees
A24: S2a adverse 8.0 9fr | B24: 16.69 | C24: agrees
A25: S2z zone 7.0@(0.75/0.88) 9fr | B25: 15.78 | C25: agrees
A26: BaseMenu statics: C1 12.26/10.46, C2 14.68/12.74, C2+ 14.56/12.49, C2a 13.08/11.14, C6 12.49/11.29 re derived and agree.
A27: Levers: L1 3.02/3.00, L2 0.79, L3 1.09 pre contingency; packages 11.28/9.47/8.11/10.38/7.46 re derived and agree.

Sheet Sensitivity
A1: Does the answer move? Fronts required under each availability scenario | L1: PURPOSE: how the fleet requirement moves with weather availability and the repair detail library.
A2: This is the case for Option 2. Option 1 swings by five fronts across the range; Option 2 holds.
A4: Scenario | B4: Floating availability (moves) | C4: Fixed availability (trade) | D4: Opt 1 cycle, days | E4: Opt 1 FRONTS | F4: Opt 2 cycle, days | G4: Opt 2 FRONTS
A5: Marine review, pessimistic | B5: 0.6 | C5: 0.8 | D5: =Inputs!$B$9/B5+(Inputs!$B$10/1)/C5+Inputs!$B$11*(1-Inputs!$B$12) | E5: =ROUNDUP((Inputs!$B$6/Inputs!$B$7)/(Inputs!$B$8/D5),0) | F5: =Inputs!$B$9/B5+(Inputs!$B$10/(1+Inputs!$B$15))/C5+Inputs!$B$11*(1-Inputs!$B$12) | G5: =ROUNDUP((Inputs!$B$6/Inputs!$B$7)/(Inputs!$B$8/F5),0)
A6: Marine review, mid | B6: 0.7 | C6: 0.85 | D6: =Inputs!$B$9/B6+(Inputs!$B$10/1)/C6+Inputs!$B$11*(1-Inputs!$B$12) | E6: =ROUNDUP((Inputs!$B$6/Inputs!$B$7)/(Inputs!$B$8/D6),0) | F6: =Inputs!$B$9/B6+(Inputs!$B$10/(1+Inputs!$B$15))/C6+Inputs!$B$11*(1-Inputs!$B$12) | G6: =ROUNDUP((Inputs!$B$6/Inputs!$B$7)/(Inputs!$B$8/F6),0)
A7: Marine review, optimistic | B7: 0.8 | C7: 0.9 | D7: =Inputs!$B$9/B7+(Inputs!$B$10/1)/C7+Inputs!$B$11*(1-Inputs!$B$12) | E7: =ROUNDUP((Inputs!$B$6/Inputs!$B$7)/(Inputs!$B$8/D7),0) | F7: =Inputs!$B$9/B7+(Inputs!$B$10/(1+Inputs!$B$15))/C7+Inputs!$B$11*(1-Inputs!$B$12) | G7: =ROUNDUP((Inputs!$B$6/Inputs!$B$7)/(Inputs!$B$8/F7),0)
A8: Draft A blanket 0.85 | B8: 0.85 | C8: 0.85 | D8: =Inputs!$B$9/B8+(Inputs!$B$10/1)/C8+Inputs!$B$11*(1-Inputs!$B$12) | E8: =ROUNDUP((Inputs!$B$6/Inputs!$B$7)/(Inputs!$B$8/D8),0) | F8: =Inputs!$B$9/B8+(Inputs!$B$10/(1+Inputs!$B$15))/C8+Inputs!$B$11*(1-Inputs!$B$12) | G8: =ROUNDUP((Inputs!$B$6/Inputs!$B$7)/(Inputs!$B$8/F8),0)
A10: Other stresses on Option 2 (mid availability unless stated)
A11: Stress | B11: Opt 2 fronts
A12: Night crew only 80 percent as productive | B12: =ROUNDUP((227/50.4)/(6/(2/0.7+(7/1.8)/0.85)),0)
A13: Marine moves take 3 days, not 2 | B13: =ROUNDUP((227/50.4)/(6/(3/0.7+(7/1.95)/0.85)),0)
A14: Repair library NOT agreed | B14: =ROUNDUP((227/50.4)/(6/(2/0.7+(7/1.95)/0.85+3)),0)
A15: Scope is 257 bents, not 227 | B15: =ROUNDUP((257/50.4)/(6/(2/0.7+(7/1.95)/0.85)),0)
A16: Pessimistic availability AND no library | B16: =ROUNDUP((227/50.4)/(6/(2/0.6+(7/1.95)/0.8+3)),0)
A18: A recommendation that holds still when the metocean lands is worth more to a risk averse board than a lower number that moves.
A19: Compressed day pattern, trades 0600 to 2200 (Option 2 pattern B) | B19: n/a | C19: 6 | D19: Both trade shifts inside 0600 to 2200; 7 at mid availability; roster subject to trade contractor confirmation

Sheet Programme
A1: SEASON PROGRAMME, Option 2 reported case | L1: PURPOSE: season splits, ramp allowance and modelled finish dates for each case.
A2: Season level calculation from the reported fronts, cycle and calendar. A dated bent by bent programme with approvals, fabrication, outages and ship calls is a hold point deliverable before the fleet order.
A4: Bents in the priority planning basis | B4: =Inputs!B6 | C4: ea | D4: Pending the STL priority and closeout register
A5: Fronts, Option 2 reported case | B5: =Options!C15 | C5: ea | D5: From the Options sheet
A6: Bents per week, one front | B6: =Options!C13 | D6: From the Options sheet
A7: Fleet rate | B7: =B5*B6 | C7: bents/wk | D7: Fronts times front rate
A8: Season 1 start | B8: 46510 | D8: After mobilisation, assembly and proof loading
A9: Season 1 available weeks | B9: 26 | C9: wk | D9: 3 May to 31 October 2027
A10: Ramp weeks at 60 percent | B10: 2 | C10: wk | D10: First fronts through the learning curve
A11: Season 1 bents | B11: =(B9-B10)*B7+B10*B7*0.6 | C11: ea | D11: Computed
A12: Carried into season 2 | B12: =B4-B11 | C12: ea | D12: Computed
A13: Season 2 start | B13: 46874 | D13: After the wet season lay up
A14: Weeks required in season 2 | B14: =B12/B7 | C14: wk | D14: Computed
A15: Modelled finish | B15: =B13+B14*7 | D15: Computed
A16: Days before the 1 November closure | B16: =DATE(2028,11,1)-B15 | C16: d | D16: Operational margin
A17: Days before the administrative end 2028 date | B17: =DATE(2028,12,31)-B15 | C17: d | D17: Contract margin
A19: ADDED AT REV B
A20: Option 1, 8 fronts at reported availabilities: season one about 118 bents, season two 23.4 weeks, modelled finish 11 Oct 2028, 21 days before closure | B20: computed
A21: C2 zone phased, fleet held: season two at 0.82 fixed availability runs 25.1 weeks, modelled finish about 23 Oct 2028, 9 days before closure | B21: computed
A22: C2+ one added season two front: 22.3 weeks, modelled finish about 4 Oct 2028, 28 days before closure | B22: computed
A23: Compressed day pattern (Option 2 pattern B), 6 fronts: campaign 46.4 weeks, finish inside season two with about 3 weeks float | B23: computed

Sheet RateCard
A1: ACCESS RATES TRACED TO THE SUPPLIER RATE CARD | L1: PURPOSE: the access supplier rate card lines used, as quoted.
A2: GGC Rate Card dated 20 August 2026, rates exclude GST. Every access rate used in this model is listed against its card line.
A4: KIT BUILD UP, one front week
A5: 4 x Kito 2 t electric chain block | B5: 200 | C5: per week each | D5: 800 | E5: Card 4.92
A6: Control panel and wireless pendant | B6: 500 | C6: per week | D6: 500 | E6: Card 4.93
A7: 4 x 9 m modular pontoon | B7: 100 | C7: per day each | D7: 2400 | E7: Card 4.7, six day week
A8: 240 v winch with davit arm, SWL 500 kg | B8: 500 | C8: per week | D8: 500 | E8: Card 4.97
A9: 20 kVA genset | B9: 1200 | C9: per week | D9: 1200 | E9: Card 4.98
A10: Kit total per front week | D10: 5400 | E10: Reconciles to Inputs B20
A12: OTHER CARD RATES USED
A13: 20 t Franna support crane | B13: 2600 | C13: per week | E13: Card 5.2, minimum hire six months; campaign is 48 weeks
A14: Scaffolder and rigger | B14: 140 | C14: per hour | E14: Card 2.4
A15: Coxswain | B15: 125 | C15: per hour | E15: Card 2.3
A16: Deckhand | B16: 110 | C16: per hour | E16: Card 2.2
A17: Blended access labour used in this model | B17: 150 | C17: per hour | E17: Above the card trades listed; conservative, covers leading hand and fitter content
A18: Living away from home allowance | B18: 300 | C18: per day | E18: Card 3.6
A19: Remote area allowance | B19: 50 | C19: per day | E19: Card 3.9
A20: Allowances used in this model | B20: 350 | C20: per day | E20: Card 3.6 plus 3.9
A21: Night shift uplift | B21: 0.3 | C21: on labour | E21: Card pricing note 6.5
A23: CARD CONDITIONS CARRIED
A24: Minimum charge out | B24: 8 hours | E24: Card 6.3; model uses 10 hour shifts
A25: Annual rate increase | B25: excluded | E25: Card 6.2; escalation is a stated exclusion
A26: Consumables at cost plus | B26: noted | E26: Card 6.9; trade consumables sit outside this access scope
A28: ACCESS LABOUR BUILD UP, from the card
A29: 5 x scaffolder or rigger | B29: 140 | C29: per hour | E29: Card 2.4
A30: 1 x coxswain | B30: 125 | C30: per hour | E30: Card 2.3
A31: 1 x deckhand | B31: 110 | C31: per hour | E31: Card 2.2
A32: Leading hand allowance | B32: 10 | C32: per hour | E32: Card 3.1, one of seven
A33: Day crew blended | B33: 135 | C33: per hour | E33: Weighted over the seven heads
A34: Day head day cost | B34: 1700 | C34: per 10 h shift | E34: Blended rate plus 350 allowances
A35: Night standby blended | B35: 117.5 | C35: per hour | E35: Coxswain and deckhand only
A36: Night head day cost | B36: 1877.5 | C36: per 10 h shift | E36: Blended rate plus 30 percent uplift, plus 350 allowances
A37: Trade labour | B37: excluded | E37: Remains inside the contractor lump sums; unchanged by this study
A39: CONTRACT SCHEDULE OF RATES USED, 2027 COLUMN
A40: Scaffolder | B40: 110 | C40: per hour | E40: Contract 4.1.2
A41: Labourer | B41: 110 | C41: per hour | E41: Contract 4.1.3
A42: Supervisor | B42: 130 | C42: per hour | E42: Contract 4.1.5
A43: Boilermaker | B43: 150 | C43: per hour | E43: Contract 4.1.1
A44: Scaffold hire, typical pilebent | B44: 88.2 | C44: per day | E44: Contract 4.2.10
A45: Compressor | B45: 310 | C45: per day | E45: Contract 4.2.4
...

Sheet NoBase
A1: OPTION 1 WITHOUT A FLOATING MARINE BASE | L1: PURPOSE: the no marine base case built line by line; ties to the Scenarios sheet first row.
A2: Requested by STL 21 August 2026. Services taken from the wharf using the existing layup areas and wharf head facilities, as described by STL. Indicative; the operability derate and the deck services build are engineering judgement and are to be tested at the proving trial.
A4: Floating availability, moves | B4: 0.8 | D4: Unchanged; workboat and crane still support moves
A5: Fixed availability, trade work | B5: 0.82 | D5: Derated from 0.90: crews transit to wharf head or layup areas for amenities and stores
A6: Effective cycle | B6: =2/B4+7/B5 | C6: days | D6: Same trade content, no night shift
A7: Bents per week, one front | B7: =6/B6 | D7: Six day week
A8: Fronts required | B8: =ROUNDUP((227/50.4)/B7,0) | C8: ea | D8: Rises from eight
A9: Campaign weeks | B9: =MIN(50.4,227/(B8*B7)) | C9: wk
A10: Access kit and support crane | B10: =(5400*B8+2600)*B9 | C10: $ | D10: Card rates, unchanged
A11: Deck based services | B11: =875*6*B9*ROUNDUP(B8/2,0) | C11: $ | D11: Generator 485, compressor 310, airprep 80 per day, one set per two fronts, contract items 4.2.2, 4.2.4 and 4.2.6
A12: Access crew labour | B12: =ROUNDUP(B8*1.3333,0)*6*B9*1471.43 | C12: $ | D12: Contract rates 4.1.2 and 4.1.5
A13: Fixed lines, marine base items removed | B13: 1480709 | C13: $ | D13: Marine standby and part of marine mobilisation removed; workboat, certification, trial and kit standby retained
A14: Subtotal | B14: =B10+B11+B12+B13 | C14: $
A15: Contingency 25 percent | B15: =B14*0.25 | C15: $
A16: TOTAL, no floating base | B16: =B14+B15 | C16: $
A17: Option 1 with the jack up | B17: =Options!B34 | C17: $ | D17: For comparison
A18: Difference | B18: =B17-B16 | C18: $ | D18: Saving from removing the base, net of the deck services it needs
A19: Fronts, with base against without | B19: =Options!B15 | C19: ea | D19: Compare with the fronts figure above

Sheet Levers
A1: COST LEVERS, rebuilt per option so every package reconciles from the lines above it | L1: PURPOSE: the savings that are real but unbanked until their conditions land, and the packages they build to.
A3: All values AUD millions. Pre contingency unless stated. Contingency 25 percent applied at package level, 15 percent at the award step.
A5: Lever | B5: Option 1 (day shift) | C5: Option 2 (day and night) | D5: Basis / what must be true
A6: Reported build, pre contingency | B6: 12.83 | C6: 11.37 | D6: Options sheet subtotals
A7: L1 Marine base: moored spud flat top at $3,000 per day in place of the manned jack up at $10,000 per day; wet standby at half rate each | B7: 3.02 | C7: 3 | D7: Written spud quotation carrying the same services; boarding in weather risk stated
A8: L2 Wet season: barge off hire and shore lay up in place of half rate standby, net of one written $120,000 remobilisation lump sum; fleet lay up care retained within existing lines | B8: 0.79 | C8: 0.79 | D8: Off hire and remobilisation terms agreed; season two availability secured
A9: L3 Night rescue reclassification: dedicated night standby crew released (Option 2 only) | B9: 0 | C9: 1.09 | D9: Safety case accepts the lifted, tied and enclosed platform as a fixed workplace; regulator concurrence
A11: PACKAGES, with 25 percent contingency unless stated
A12: Reported base | B12: 16.04 | C12: 14.22 | D12: As issued
A13: Credible: L1 plus L2 | B13: 11.28 | C13: 9.47 | D13: (pre cont minus L1 minus L2) x 1.25
A14: Stretch: plus L3 (Option 2 only) | B14: 11.28 | C14: 8.11 | D14: (pre cont minus L1 minus L2 minus L3) x 1.25
A15: Stretch at 15 percent contingency on award | B15: 10.38 | C15: 7.46 | D15: Same base x 1.15, at controlled basis of estimate
A16: Against the $9.24M priced allowance | B16: 2.04 | C16: 0.23 | D16: Credible package minus allowance; stretch Option 2 sits below it
A18: Kit ownership lever retained as a threshold test: buy below about $320,000 per front against the hire plus standby breakeven; fabrication drawings exist.

Sheet BaseMenu
A1: MARINE BASE CONCEPTS, each carried with its own cycle and availability assumption | L1: PURPOSE: the base arrangements as carried in the report Section 9 table, with each concept’s own availability basis.
A2: Access totals AUD millions with 25 percent contingency. Net is against the reported case for the same option. Wet season fleet lay up care is retained in every concept; the change register records this recharacterisation.
A4: Concept | B4: Opt 1 total | C4: Opt 1 net | D4: Opt 2 total | E4: Opt 2 net | F4: Fleet / finish effect | G4: Cycle and availability basis; what must be true
A5: C0 Reported case: manned jack up as static base, whole campaign | B5: 16.04 | C5: 0 | D5: 14.22 | E5: 0 | F5: 8 / 5 fronts; finish 11 Oct 2028 (Option 1), 9 Oct 2028 (Option 2) | G5: Services afloat; fixed availability 0.90; ABH written reconciliation in progress
A6: C1 Moored spud flat top, whole campaign, same services | B6: 12.26 | C6: 3.78 | D6: 10.46 | E6: 3.76 | F6: Fleet unchanged; finish unchanged | G6: Written spud quote at or near $3,000 per day; boarding in weather risk carried as sensitivity
A7: C2 Zone phased: jack up through season one (Zone 3), deck serviced season two (Zones 2 and 1), fleet held | B7: 14.68 | C7: 1.36 | D7: 12.74 | E7: 1.48 | F7: Fleet held; finish about 23 Oct 2028, float 9 days | G7: Season two fixed availability derated 0.90 to 0.82 for shore servicing; one powered welfare set on deck; wet fleet care retained
A8: C2+ Zone phased with one added season two front, date held | B8: 14.56 | C8: 1.48 | D8: 12.49 | E8: 1.73 | F8: One extra front season two; finish about 4 Oct 2028 | G8: As C2 with the season two rate restored by fleet
A9: C2a Zone phased on a spud flat top in season one | B9: 13.08 | C9: 2.96 | D9: 11.14 | E9: 3.08 | F9: As C2 | G9: As C2 plus the written spud quotation
A10: C3 Self sufficient fronts: powered set per front added for resilience | B10: 18.59 | C10: -2.55 | D10: 15.8 | E10: -1.58 | F10: Fleet unchanged | G10: Adds contract items 4.2.2, 4.2.4, 4.2.6 per front; pairs with C2 season two or C6
A11: C4 Wharf deck service train | B11: POA | D11: POA | F11: Roadway movements return | G11: Welfare, stores and davit handling from the deck; priced on STL confirmation of laydown and power points
A12: C5 Dry hire moored deck | B12: POA | D12: POA | F12: As C1 | G12: Whether a bargemaster requirement attaches to a moored flat top; marine authority position at HP5
A13: C6 No marine base at all | B13: 12.49 | C13: 3.55 | D13: 11.29 | E13: 2.93 | F13: 9 / 6 fronts; fixed availability falls to 0.82 | G13: Crew transit arithmetic: about 12 minutes each way plus crib runs, about 58 minutes per 10 hour shift, an 8 percent derate; services queue on the 8 tonne roadway
A15: Counterweight: one work front costs about $0.27M per season in kit and crane share plus fabrication against the $320,000 buy or hire breakeven. A concept that costs the campaign two fronts returns most of its saving.
A16: Pre adjustment working figures for the same concepts: C1 $3.76M, C2 $3.09M, C2a $4.68M. The nets in this sheet apply the season two availability derate and retained fleet care; both sets shown so the adjustment is visible.
