Workbook

Sheet 00 Read Me
A1: STL Lucinda Access Methodology - Productivity and Cost Model
A2: Commercial in confidence | All fees and costs AUD ex GST unless stated otherwise
A3: Document ID | B3: ED-018-2026-07
A4: Revision | B4: A - internal working model
A5: Date | B5: 20 August 2026
A6: Prepared by | B6: Endura Decommissioning (Van Iersel Projects Pty Ltd)
A7: Purpose | B7: Formula-driven comparison of the current scaffold methodology and the candidate reusable marine access system. Supports Stage 1 methodology, programme, cost and risk assessment.
A8: Assurance status | B8: Concept-stage working model. Not for construction, procurement or cost commitment.
A9: Key rule | B9: Claimed payment-stage equivalents are not treated as completed bents. Proposed rates are QA-closed bents/week only where the full cycle is represented.
A10: Input colour | B10: Pale yellow = user/supplier input; green = project evidence; blue = formula; red = missing/gating input.
A11: Current limitation | B11: Headstock containment, below-LAT jacket installation, full coating elapsed holds, supplier platform configuration, JUB staging and current bent register remain open.
A12: Required stress test | B12: 227 bents / 60 nominal production weeks = 3.783 QA-closed bents/week. This is a conservative whole-scope stress test, not confirmation that all 227 are priority repairs.
A13: Recommended use | B13: Use the model to test access sets, weld crews, approval strategy, shifts and verified supplier rates. Do not quote a total cost while red/TBC inputs remain.
A15: Repository rate extraction | B15: 0 currency/rate candidate lines were extracted to 06 Rate Register. Every candidate remains Use in model = N until checked against the original GGC/supplier source.

Sheet 01 Source Manifest
A1: Source Manifest and Extraction Coverage
A3: No. | B3: Repository path | C3: Type | D3: Size (MB) | E3: SHA-256 | F3: Extraction status | G3: Pages/sheets | H3: Text chars | I3: Review relevance | J3: Current/superseded | K3: Notes

Sheet 02 Proposal Compliance
A1: Stage 1 Proposal Deliverable Compliance Matrix
A3: ID | B3: Proposal commitment / required output | C3: Current package treatment | D3: Evidence / workbook sheet | E3: Status | F3: Action before STL issue
A4: D01 | B4: Review project information, contract, drawings, reports, programme and current progress | C4: Source manifest and baseline review | D4: 01 Source Manifest; 03 Current Baseline; 04 Current Schedule | E4: Covered | F4: Maintain controlled source register and close unreadable/native schedule limitations.
A5: D02 | B5: Define and screen access methodology options | C5: Current scaffold, reusable marine access and hybrid/special-bent pathways | D5: Methodology Sections 4-5; 12 Comparison | E5: Covered | F5: Add formal weighted option-screening table after supplier input.
A6: D03 | B6: Define working configuration and equipment make-up | C6: Two long-face platforms, traversing decks, half-shell containment, access towers, JUB and workboat | D6: 05 Proposed WBS; 08 Productivity | E6: Concept defined | F6: Close platform, winch, traversing deck and containment supplier data.
A7: D04 | B7: Define deployment and bent-to-bent relocation | C7: Detailed mobilisation, pre-rig, float-in, lift, service connection, lower and tow sequence | D7: 05 Proposed WBS; 10 Programme | E7: Covered conceptually | F7: Validate by timed trial and marine operations plan.
A8: D05 | B8: Assess tide, weather and operability | C8: Activity-specific weather/tide gates and residual availability input | D8: 08 Productivity; 10 Programme; 13 Risks | E8: Partial | F8: Build dated metocean/ship-call calendar from STL records.
A9: D06 | B9: Develop containment and waste-recovery approach | C9: Pile half-shell and headstock enclosure gate, negative pressure, abrasive/wash-water recovery | D9: 05 Proposed WBS; 13 Risks | E9: Partial | F9: Supplier design and environmental acceptance criteria required.
A10: D07 | B10: Define materials, waste and crew logistics | C10: JUB service base, water logistics, crew by road, access towers, rescue craft | D10: 05 Proposed WBS; 07 Cost Build-Up | E10: Covered conceptually | F10: Resource-load JUB, workboats, fuel, waste and accommodation.
A11: D08 | B11: Assess structural interfaces and temporary loading | C11: Hang-off points, sliding clamps, platform states, traversing deck and containment interfaces | D11: 13 Risks & RFIs | E11: Open gate | F11: RPEQ temporary-works design and independent check required.
A12: D09 | B12: Define cyclone, wet-season and ship-call response | C12: Full seasonal demob, two-day make-safe, fleet recovery and refuge requirements | D12: 10 Programme; 13 Risks | E12: Partial | F12: Time and resource-load recovery with selected fleet/JUB.
A13: D10 | B13: Compare productivity, programme, cost and risk with current method | C13: Formula-driven baseline and scenarios; cost build-up and comparison | D13: 03, 07, 08, 09, 10, 11, 12 | E13: Covered with gaps | F13: Close supplier rates and remaining bent register.
A14: D11 | B14: Undertake supplier and contractor market soundings | C14: GGC/Hansen platform data, JUB candidates, raw rate register | D14: 06 Rate Register; 13 Risks | E14: In progress | F14: Obtain written GGC quote, containment proposal and JUB availability/rates.
... A16: D13 | B16: Issue final report with recommended methodology and implementation roadmap | C16: Companion detailed report and roadmap | D16: DOCX report; 10 Programme | E16: Draft prepared | F16: Update after workshop and market sounding.

Sheet 03 Current Baseline
A1: Current AAB Methodology - Progress and Cycle Baseline
A3: Stage | B3: Claimed quantity Mar-Jul 2026 | C3: Unit | D3: Period weeks | E3: Calculated rate/week | F3: Best month | G3: Verification note
A4: Provision of safe access | B4: 7.9 | C4: bent equivalent | D4: 21.9 | E4: =B4/D4 | F4: 3.2 | G4: Payment-stage equivalent, not completed bent
A5: Clean, inspect, UT and weld determination | B5: 9 | C5: bent equivalent | D5: 21.9 | E5: =B5/D5 | F5: 5 | G5: Payment-stage equivalent
A6: Abrasive blast and coating application | B6: 7 | C6: bent equivalent | D6: 21.9 | E6: =B6/D6 | F6: 3.5 | G6: Payment-stage equivalent
A7: Denso / petrolatum jacket installation | B7: 12 | C7: pile equivalent | D7: 21.9 | E7: =B7/D7 | F7: 7.3 | G7: Pile equivalent
A8: Weld preparation and welding | B8: 473.025 | C8: lm | D8: 21.9 | E8: =B8/D8 | F8: 202.0 lm in Jun | G8: 183.86 lm at 8 mm + 289.165 lm at 10 mm
A12: Current cycle activity | B12: Low days | C12: High days | D12: Central days | E12: Character | F12: Source / limitation
A13: Scaffold erection and encapsulation | B13: 2 | C13: 3 | D13: 2.5 | E13: Access handling | F13: Contract programme / validated screenshots; native logic requires planner confirmation
A14: High pressure wash, inspection, UT | B14: 1 | C14: 1 | D14: 1 | E14: Productive | F14: Contract programme / validated screenshots; native logic requires planner confirmation
A15: Weld repairs | B15: 2 | C15: 7 | D15: 4.5 | E15: Productive, variable | F15: Contract programme / validated screenshots; native logic requires planner confirmation
A16: Repair approval hold | B16: 3 | C16: 3 | D16: 3 | E16: Waiting | F16: Contract programme / validated screenshots; native logic requires planner confirmation
A17: Abrasive blast and two coats | B17: 3 | C17: 4 | D17: 3.5 | E17: Productive | F17: Contract programme / validated screenshots; native logic requires planner confirmation
A18: Pile jacket installation | B18: 0 | C18: 2 | D18: 1 | E18: Tide limited | F18: Contract programme / validated screenshots; native logic requires planner confirmation
A19: Scaffold strip and relocation | B19: 1 | C19: 2 | D19: 1.5 | E19: Access handling | F19: Contract programme / validated screenshots; native logic requires planner confirmation
A21: Representative cycle subtotal (excl Sundays/float) | D21: =SUM(D13:D19)
A22: Programme typical elapsed basis | D22: 15 | F22: Programme screenshots indicate approximately 14-15 calendar days; earlier stress allowance used 16 days.
A24: Current contract access basis (firm scope) | B24: 9275472.4 | C24: AUD ex GST | F24: Historical contract access basis, not remaining avoidable cost. Reconcile to current certified claims before commercial use.
A25: Access basis per firm bent | B25: =B24/237 | C25: AUD/bent

Sheet 04 Current Schedule
A1: Current Contractor Programme - Native and Screenshot Review
A3: Field | B3: Value | C3: Assurance status | D3: Comment
A4: Native MPP file | B4: AAB Program (June 26).mpp | C4: Supplied | D4: Native file inventoried; task extraction included below if available.
A5: Programme typical bent cycle | B5: 14-15 calendar days | C5: Cross-checked | D5: Matches supplied programme screenshots; do not relabel as 16 working days.
A6: Scaffold sets physically reported | B6: 4 sets | C6: Project evidence | D6: Do not infer access inventory from total WIP.
A7: Peak bents concurrently in progress | B7: Up to 9 | C7: Programme observation | D7: WIP is not the same as nine scaffold sets.
A8: Planned production order | B8: Approximately 2 bents/week | C8: Client/programme basis | D8: Confirm against final baseline and current reforecast.
A9: Native critical path | B9: Not independently verified | C9: Clearance limitation | D9: Task links/calendars/constraints/float need planner-issued export.
A12: UID | B12: ID | C12: Task name | D12: Duration | E12: Start | F12: Finish | G12: Actual start | H12: Actual finish | I12: % complete | J12: Critical | K12: Summary | L12: Total slack
A13: NOT EXTRACTED | C13: Native MPP task table unavailable to this build; use screenshot-validated summary above.

Sheet 05 Proposed WBS
A1: Proposed Marine Access Methodology - Detailed Activity Library
A3: WBS | B3: Phase | C3: Activity | D3: Workfront / crew | E3: Unit | F3: Qty per typical bent | G3: Active shifts | H3: Elapsed hold days | I3: Occupies access set | J3: Can overlap ahead | K3: Basis class | L3: Source / verification | M3: Cost code
A4: 1.1 | B4: Engineering | C4: Bathymetric and seabed survey | D4: Survey contractor | E4: campaign | F4: 1 | I4: No | J4: Yes | K4: Open input | L4: STL RFI / supplier requirements | M4: ENG-SURV
A5: 1.2 | B5: Engineering | C5: Temporary works design: hang-off, sliding clamps, platforms and traversing decks | D5: RPEQ/TW engineer | E5: campaign | F5: 1 | I5: No | J5: Yes | K5: Open input | L5: Supplier data required | M5: ENG-TW
A6: 1.3 | B6: Engineering | C6: Containment design and environmental acceptance | D6: Containment supplier / HSE | E6: campaign | F6: 1 | I6: No | J6: Yes | K6: Open input | L6: Supplier design required | M6: ENG-CONT
A7: 1.4 | B7: Engineering | C7: Marine operations plan, SIMOPS, rescue, ship and cyclone response | D7: Marine engineer | E7: campaign | F7: 1 | I7: No | J7: Yes | K7: Open input | L7: Stage 1 deliverable | M7: ENG-MAR
A8: 2.1 | B8: Mobilisation | C8: Transport and assemble modular platforms | D8: GGC / rigging crew | E8: access set | F8: 1 | I8: No | J8: Yes | K8: Supplier input | L8: GGC rates and Hansen drawings | M8: MOB-PLAT
A9: 2.2 | B9: Mobilisation | C9: Install winches, travelling supports and controls | D9: GGC / electricians / riggers | E9: access set | F9: 1 | I9: No | J9: Yes | K9: Supplier input | L9: GGC written confirmation required | M9: MOB-WINCH
A10: 2.3 | B10: Mobilisation | C10: Assemble traversing decks and containment halves | D10: Access / containment crew | E10: access set | F10: 1 | I10: No | J10: Yes | K10: Supplier input | L10: Supplier design required | M10: MOB-CONT
A11: 2.4 | B11: Mobilisation | C11: Proof load, function test and rescue drill | D11: TW engineer / marine crew | E11: access set | F11: 1 | I11: No | J11: Yes | K11: Required gate | L11: Before first use | M11: MOB-TEST
A12: 3.1 | B12: Advance rigging | C12: Install/advance hang-off and clamp package at next bent | D12: Rigging crew | E12: bent | F12: 1 | G12: 0.4 | H12: 0 | I12: No | J12: Yes | K12: Engineering assumption | L12: 4 h share in relocation model | M12: REL-RIG
A13: 3.2 | B13: Relocation | C13: Disconnect services and lower platform pair | D13: Platform crew | E13: bent | F13: 1 | G13: 0.1 | H13: 0 | I13: Yes | J13: No | K13: Engineering assumption | L13: 1 h | M13: REL-LOWER
A14: 3.3 | B14: Relocation | C14: Tow platform pair to next bent | D14: Workboat / platform crew | E14: bent | F14: 1 | G14: 0.2 | H14: 0 | I14: Yes | J14: No | K14: Engineering assumption | L14: 2 h | M14: REL-TOW
A15: 3.4 | B15: Relocation | C15: Position, hook-on, lift, level and restrain | D15: Platform crew / workboat | E15: bent | F15: 1 | G15: 0.2 | H15: 0 | I15: Yes | J15: No | K15: Engineering assumption | L15: 2 h | M15: REL-LIFT
A16: 3.5 | B16: Relocation | C16: Move and secure access tower | D16: JUB crane / riggers | E16: bent | F16: 1 | G16: 0.1 | H16: 0 | I16: Yes | J16: No | K16: Engineering assumption | L16: 1 h | M16: REL-TOWER
A17: 3.6 | B17: Relocation | C17: Install traversing decks, services and commissioning checks | D17: Platform crew | E17: bent | F17: 1 | G17: 0.1 | H17: 0 | I17: Yes | J17: No | K17: Engineering assumption | L17: 1 h | M17: REL-SERVICE
A18: 4.1 | B18: Diagnostic | C18: Remove existing wrapping, wash, inspect and UT | D18: Survey / inspection crew | E18: bent | F18: 1 | G18: 1 | H18: 0 | I18: Yes | J18: No | K18: Project/programme basis | L18: Inspection front | M18: DIAG-INSP
A19: 4.2 | B19: Diagnostic | C19: Install half-shell and diagnostic blast both upper pile bands | D19: Blast crew | E19: 27-29 m2 | F19: 1 | G19: 1 | H19: 0 | I19: Yes | J19: No | K19: Engineering assumption | L19: One shift conservative allowance incl moves/QA | M19: DIAG-BLAST
A20: 4.3 | B20: Diagnostic | C20: Headstock diagnostic preparation and mark-up | D20: Blast / inspection crew | E20: bent | F20: 1 | I20: Yes | J20: No | K20: NOT MODELLED | L20: Headstock enclosure method required | M20: DIAG-HEAD
A21: 4.4 | B21: Diagnostic | C21: Mark-up both piles and headstock; prepare bent repair package | D21: Engineer / inspector | E21: bent | F21: 1 | G21: 0.5 | H21: 0 | I21: Yes | J21: No | K21: Engineering assumption | L21: Bent-level submission basis requires confirmation | M21: DIAG-MARK
A22: 4.5 | B22: Approval | C22: Bent-level repair design review and approval hold | D22: Reviewing engineer / STL | E22: bent | F22: 1 | G22: 0 | H22: 3 | I22: Yes | J22: Yes elsewhere | K22: Programme basis / assumption | L22: One hold assumes full bent exposed first | M22: APP-HOLD
A23: 5.1 | B23: Repair | C23: Repair steel detail, prefabrication and delivery | D23: Fabrication crew | E23: lm | F23: 53 | G23: 0 | H23: 0 | I23: No | J23: Yes | K23: Client payment quantity | L23: Prefabricate from approved package | M23: REP-FAB
A24: 5.2 | B24: Repair | C24: Pile 1 fit-up, welding, NDT and rectification | D24: Weld crews | E24: lm | F24: 26.5 | G24: =53/(2*6)/2 | H24: 0 | I24: Yes | J24: No | K24: Sensitivity | L24: 2 crews x 6 accepted lm/crew-shift base | M24: REP-WELD
A25: 5.3 | B25: Repair | C25: Pile 1 post-weld preparation | D25: Blast/prep crew | E25: pile | F25: 1 | G25: 0.25 | H25: 0 | I25: Yes | J25: No | K25: Engineering assumption | L25: To verify at trial | M25: REP-PREP
A26: 5.4 | B26: Coating | C26: Pile 1 coat 1, stripe coats, wash/dry, coat 2 and QA | D26: Coating crew | E26: pile | F26: 1 | G26: 0.75 | I26: Yes | J26: Limited | K26: NOT FULLY MODELLED | L26: Active work only; elapsed recoat hold requires dated work lot | M26: COAT-P1
A27: 5.5 | B27: Jackets | C27: Pile 1 petrolatum jacket above LAT | D27: Jacket crew | E27: pile | F27: 1 | G27: 0.5 | H27: 0 | I27: Yes | J27: No | K27: Engineering assumption | L27: Timed trial required | M27: JKT-P1
A28: 5.6 | B28: Jackets | C28: Pile 1 jacket below LAT and lower termination | D28: Marine/jacket crew | E28: pile | F28: 1 | I28: Yes | J28: No | K28: NOT MODELLED | L28: Manufacturer/marine method required | M28: JKT-SUB
A29: 5.7 | B29: Repair | C29: Repeat repair, coating and jacket sequence on pile 2 | D29: All trade crews | E29: pile | F29: 1 | G29: =G25+G26+G27+G28 | I29: Yes | J29: No | K29: Formula / concept | L29: Same platform remains at bent | M29: REP-P2
A30: 5.8 | B30: Headstock | C30: Headstock containment, repair, coating, gallery feet and keeper-angle interfaces | D30: Multi-trade | E30: bent | F30: 1 | I30: Yes | J30: No | K30: NOT MODELLED | L30: Bent-family design required | M30: HEAD-WORK
A31: 6.1 | B31: Closeout | C31: Containment clean-out, final QA, records, rework and bent release | D31: QA / all trades | E31: bent | F31: 1 | I31: Yes | J31: No | K31: NOT MODELLED | L31: Trial and ITP required | M31: QA-CLOSE
A32: 7.1 | B32: Seasonal | C32: Ship-call make-safe and restart | D32: Marine / all crews | E32: event | F32: 1 | I32: Varies | J32: No | K32: Calendar event | L32: 2-day notice basis; exact scope to define | M32: OPS-SHIP
A33: 7.2 | B33: Seasonal | C33: Wet-season full demobilisation and remobilisation | D33: All marine spread | E33: season | F33: 1 | I33: No | J33: No | K33: Client requirement | L33: Dec-Mar basis | M33: OPS-SEASON
A34: 7.3 | B34: Seasonal | C34: Cyclone fleet recovery to refuge and reinstatement | D34: Marine spread | E34: event | F34: 1 | I34: No | J34: No | K34: Required gate | L34: Timed recovery plan required | M34: OPS-CYCLONE

Sheet 06 Rate Register
A1: Supplier, Labour and Plant Rate Register
A3: Rate ID | B3: Category | C3: Description / source context | D3: Amount | E3: Currency | F3: Rate unit | G3: Source file | H3: Source line | I3: Use in model? | J3: Confidence | K3: Notes
A4: R001 | B4: Current access | C4: Contract access basis for firm scope | D4: 9275472.4 | E4: AUD | F4: lump sum | G4: AAB contract/assurance calculation | H4: n/a | I4: N | J4: Verified historical basis | K4: Not remaining avoidable cost

Sheet 07 Cost Build Up
A1: Candidate Methodology - Detailed Cost Build-Up
A2: WARNING: Total is incomplete while any TBC rate or quantity remains. Rates are AUD ex GST.
A4: Cost code | B4: Cost group | C4: Item | D4: Qty | E4: Unit | F4: Rate | G4: Duration / multiplier | H4: Extended cost | I4: Rate status | J4: Source / note
A5: ENG-SURV | B5: Engineering | C5: Bathymetric and seabed survey | D5: 1 | E5: LS | G5: 1 | H5: =IF(OR(F5="",G5=""),"TBC",D5*F5*G5) | I5: TBC | J5: Obtain supplier quote
A6: ENG-TW | B6: Engineering | C6: Temporary works design and independent check | D6: 1 | E6: LS | G6: 1 | H6: =IF(OR(F6="",G6=""),"TBC",D6*F6*G6) | I6: TBC | J6: Platform/hang-off/traversing decks
A7: ENG-CONT | B7: Engineering | C7: Containment and environmental design | D7: 1 | E7: LS | G7: 1 | H7: =IF(OR(F7="",G7=""),"TBC",D7*F7*G7) | I7: TBC | J7: Pile and headstock configurations
A8: ENG-MAR | B8: Engineering | C8: Marine operations plan, SIMOPS, rescue and seasonal plans | D8: 1 | E8: LS | G8: 1 | H8: =IF(OR(F8="",G8=""),"TBC",D8*F8*G8) | I8: TBC | J8: Stage 1 / execution engineering
A9: MOB-JUB | B9: Mobilisation | C9: JUB mobilisation to Lucinda | D9: 1 | E9: LS | G9: 1 | H9: =IF(OR(F9="",G9=""),"TBC",D9*F9*G9) | I9: TBC | J9: Candidate unit required
A10: MOB-PLAT | B10: Mobilisation | C10: GGC platform transport, assembly and modification | D10: 1 | E10: campaign | G10: 1 | H10: =IF(OR(F10="",G10=""),"TBC",D10*F10*G10) | I10: TBC | J10: Use written GGC quote
A11: MOB-CONT | B11: Mobilisation | C11: Containment/traversing deck fabrication and assembly | D11: 1 | E11: campaign | G11: 1 | H11: =IF(OR(F11="",G11=""),"TBC",D11*F11*G11) | I11: TBC | J11: Supplier quote
A12: MOB-TEST | B12: Mobilisation | C12: Proof load and proving campaign | D12: 1 | E12: campaign | G12: 1 | H12: =IF(OR(F12="",G12=""),"TBC",D12*F12*G12) | I12: TBC | J12: Include engineering attendance
A13: TIME-JUB | B13: Time-related | C13: Jack-up barge hire | D13: 1 | E13: day | G13: 0 | H13: =IF(OR(F13="",G13=""),"TBC",D13*F13*G13) | I13: TBC | J13: Duration from dated programme
A14: TIME-WB | B14: Time-related | C14: Primary workboat / multicat hire | D14: 1 | E14: day | G14: 0 | H14: =IF(OR(F14="",G14=""),"TBC",D14*F14*G14) | I14: TBC | J14: Campaign duration
A15: TIME-RB | B15: Time-related | C15: Dedicated rescue craft | D15: 1 | E15: day | G15: 0 | H15: =IF(OR(F15="",G15=""),"TBC",D15*F15*G15) | I15: TBC | J15: Whenever personnel over water
A16: TIME-PLAT | B16: Time-related | C16: Floating platform/access set hire | D16: 1 | E16: set-day | G16: 0 | H16: =IF(OR(F16="",G16=""),"TBC",D16*F16*G16) | I16: TBC | J16: Fleet output from model
... A39: CONT | B39: Contingency | C39: Risk allowance | D39: 1 | E39: % | G39: 0 | H39: =IF(OR(F39="",G39=""),"TBC",D39*F39*G39) | I39: TBC | J39: Apply after estimate basis is complete
G41: Subtotal of completed numeric lines | H41: =SUM(H5:H39)
G42: Estimate completeness | H42: =COUNT(H5:H39)/35
G43: Issue status | H43: =IF(H42=1,"Complete arithmetic only - subject to assurance","INCOMPLETE - TBC inputs remain")

Sheet 08 Productivity
A1: Proposed Productivity Model - Access-Set Occupancy
A3: Input | B3: Value | C3: Unit | D3: Basis / note
A4: Whole-scope stress quantity | B4: 227 | C4: bents | D4: Unverified stress case pending bent register
A5: Nominal production seasons | B5: 2 | C5: seasons | D5: 2027 and 2028
A6: Nominal weeks per season | B6: 30 | C6: weeks | D6: Before explicit calendar losses
A7: Required net stress rate | B7: =B4/(B5*B6) | C7: bents/week | D7: 227 / 60
A8: Working days per week | B8: 6 | C8: days/week | D8: Planning input
A9: Shifts per day | B9: 1 | C9: shift/day | D9: Night production not assumed
A10: Residual stochastic availability | B10: 0.85 | C10: factor | D10: Weather/breakdown only; known outages explicit
A11: Weld quantity per typical bent | B11: 53 | C11: lm | D11: Payment-equivalent sensitivity, not design quantity
A12: Weld crews per access set | B12: 2 | C12: crews | D12: Base sensitivity
A13: Accepted weld output per crew shift | B13: 6 | C13: lm/crew-shift | D13: Unverified central sensitivity
A14: Repair approval hold | B14: 3 | C14: days | D14: Bent-level approval basis requiring confirmation
A15: Relocation hours per bent | B15: 11 | C15: h | D15: Advance rigging + move package
A16: Hours per shift | B16: 10 | C16: h | D16: Planning input
A17: Headstock containment/work | B17: 0 | C17: shifts | D17: NOT MODELLED; enter only with evidence
A18: Below-LAT jacket work | B18: 0 | C18: shifts | D18: NOT MODELLED
A19: Containment cleanout/QA/rework | B19: 0 | C19: shifts | D19: NOT MODELLED
A20: Coating elapsed hold occupancy | B20: 0 | C20: days | D20: NOT MODELLED; dated work-lot required
A23: Model activity | B23: Base active/hold shifts | C23: Formula / basis | D23: Status
A24: Wash, inspect and UT | B24: 1 | C24: Project/programme basis | D24: Included
A25: Diagnostic blast: two upper pile bands | B25: 1 | C25: ~27-29 m2; conservative incl containment moves/QA | D25: Included
A26: Mark-up and bent repair package | B26: 0.5 | C26: Engineering assumption | D26: Included
A27: Repair approval hold | B27: =B14 | C27: One bent-level hold; confirm | D27: Included assumption
A28: Welding and NDT | B28: =B11/(B12*B13) | C28: Weld qty / crews / accepted rate | D28: Largest modelled item
A29: Post-weld preparation | B29: 0.5 | C29: Engineering assumption | D29: Included
A30: Coating active work | B30: 1.5 | C30: Does not include elapsed recoat holds | D30: Included active only
A31: Jacket active work above LAT | B31: 1 | C31: Timed trial required | D31: Included assumption
A32: Headstock containment/work | B32: =B17 | C32: User evidence input | D32: NOT MODELLED if zero
A33: Below-LAT jacket work | B33: =B18 | C33: User evidence input | D33: NOT MODELLED if zero
A34: Cleanout/QA/rework | B34: =B19 | C34: User evidence input | D34: NOT MODELLED if zero
A35: Coating elapsed hold occupancy | B35: =B20 | C35: User evidence input | D35: NOT MODELLED if zero
A36: Relocation | B36: =B15/B16 | C36: 11 h / shift hours | D36: Included
A38: Total access-set occupancy cycle | B38: =SUM(B24:B36) | C38: shifts/days at one shift/day; still concept-stage
A39: Rate per access set | B39: =B8*B9*B10/B38 | C39: bents/week/set
A40: Sets required for stress rate | B40: =ROUNDUP(B7/B39,0) | C40: mathematical sensitivity, not recommended fleet
A43: Access sets | B43: Calculated bents/week | C43: Weeks for 227 bents | D43: Nominal seasons | E43: Gap to 3.783/week
A44: 1 | B44: =A44*$B$39 | C44: =$B$4/B44 | D44: =C44/$B$6 | E44: =B44-$B$7
A45: 2 | B45: =A45*$B$39 | C45: =$B$4/B45 | D45: =C45/$B$6 | E45: =B45-$B$7
A46: 3 | B46: =A46*$B$39 | C46: =$B$4/B46 | D46: =C46/$B$6 | E46: =B46-$B$7
...

Sheet 09 Fleet Scenarios
A1: Fleet and Welding Capacity Sensitivities
A3: Scenario | B3: Weld crews/set | C3: Accepted lm/crew-shift | D3: Routine approval hold (d) | E3: Other fixed shifts | F3: Relocation shifts | G3: Cycle shifts | H3: Rate/set/week | I3: Sets required | J3: Indicative weld crews | K3: Status / interpretation
A4: S1 Base incomplete | B4: 2 | C4: 6 | D4: 3 | E4: ='08 Productivity'!B17+'08 Productivity'!B18+'08 Productivity'!B19+'08 Productivity'!B20+5.5 | F4: ='08 Productivity'!B15/'08 Productivity'!B16 | G4: =E4+(53/(B4*C4))+D4+F4 | H4: ='08 Productivity'!B8*'08 Productivity'!B9*'08 Productivity'!B10/G4 | I4: =ROUNDUP('08 Productivity'!B7/H4,0) | J4: =B4*I4 | K4: Diagnostic sensitivity only; open activities remain.
A5: S2 Improved welding | B5: 4 | C5: 8 | D5: 3 | E5: ='08 Productivity'!B17+'08 Productivity'!B18+'08 Productivity'!B19+'08 Productivity'!B20+5.5 | F5: ='08 Productivity'!B15/'08 Productivity'!B16 | G5: =E5+(53/(B5*C5))+D5+F5 | H5: ='08 Productivity'!B8*'08 Productivity'!B9*'08 Productivity'!B10/G5 | I5: =ROUNDUP('08 Productivity'!B7/H5,0) | J5: =B5*I5 | K5: Diagnostic sensitivity only; open activities remain.
A6: S3 Repair library / reduced hold | B6: 4 | C6: 8 | D6: 0 | E6: ='08 Productivity'!B17+'08 Productivity'!B18+'08 Productivity'!B19+'08 Productivity'!B20+5.5 | F6: ='08 Productivity'!B15/'08 Productivity'!B16 | G6: =E6+(53/(B6*C6))+D6+F6 | H6: ='08 Productivity'!B8*'08 Productivity'!B9*'08 Productivity'!B10/G6 | I6: =ROUNDUP('08 Productivity'!B7/H6,0) | J6: =B6*I6 | K6: Diagnostic sensitivity only; open activities remain.
A7: S4 Strong weld + reduced hold | B7: 6 | C7: 10 | D7: 0 | E7: ='08 Productivity'!B17+'08 Productivity'!B18+'08 Productivity'!B19+'08 Productivity'!B20+5.5 | F7: ='08 Productivity'!B15/'08 Productivity'!B16 | G7: =E7+(53/(B7*C7))+D7+F7 | H7: ='08 Productivity'!B8*'08 Productivity'!B9*'08 Productivity'!B10/G7 | I7: =ROUNDUP('08 Productivity'!B7/H7,0) | J7: =B7*I7 | K7: Upper-bound sensitivity; not executable without proving.

Sheet 10 Programme
A1: Indicative Stage 1 to Execution Programme and Calendar Gates
A3: WBS | B3: Activity | C3: Responsible party | D3: Start basis | E3: Duration weeks | F3: Predecessor | G3: Calendar treatment | H3: Output / acceptance
A4: A1 | B4: STL confirm priority and remaining bent register | C4: STL | D4: Immediate | E4: 1 | F4: None | G4: Working days | H4: As-at-date register by bent/family/status
A5: A2 | B5: Bathymetric/seabed and metocean data confirmation | C5: STL / surveyor | D5: Immediate | E5: 4 | F5: None | G5: Marine survey window | H5: Data accepted for JUB/platform design
A6: A3 | B6: GGC platform/containment technical and commercial offer | C6: GGC | D6: Immediate | E6: 2 | F6: None | G6: Calendar | H6: Dimensions, mass, capacity, winch, availability, rates
A7: A4 | B7: JUB/workboat market sounding and quotes | C7: Endura / suppliers | D7: Immediate | E7: 2 | F7: None | G7: Calendar | H7: Candidate spread, availability, rate and limitations
A8: A5 | B8: Concept option screening and STL workshop | C8: Endura / STL | D8: After A1-A4 initial | E8: 1 | F8: A1,A3,A4 | G8: Working days | H8: Selected direction and actions
A9: B1 | B9: Temporary works concept and load-path design | C9: Execution contractor/RPEQ | D9: After supplier selection | E9: 6 | F9: A2,A3,A5 | G9: Working days | H9: Checked concept drawings and load schedule
A10: B2 | B10: Containment/headstock/below-LAT method development | C10: Supplier / engineer | D10: After supplier selection | E10: 6 | F10: A3,A5 | G10: Working days | H10: Accepted method and cycle basis
A11: B3 | B11: Marine operations, SIMOPS, environmental and approvals plan | C11: Marine/HSE team | D11: After A2,A4 | E11: 8 | F11: A2,A4,A5 | G11: Working days | H11: Approval-ready plans
A12: B4 | B12: Detailed cost, dated programme and procurement strategy | C12: Endura | D12: After B1-B3 | E12: 4 | F12: B1,B2,B3 | G12: Working days | H12: Board-ready comparison
A13: C1 | B13: Fabricate/modify access sets and containment | C13: Supplier | D13: After approval | E13: 10 | F13: B1,B2,B4 | G13: Calendar/long lead | H13: Factory acceptance and load test
A14: C2 | B14: Mobilise marine spread and establish shore base | C14: Contractor | D14: Dry-season start | E14: 3 | F14: C1,B3 | G14: Marine weather | H14: Ready for proving
A15: C3 | B15: Two-set proving campaign on representative bent families | C15: Contractor / Endura / STL | D15: After C2 | E15: 4 | F15: C2 | G15: Dated calendar | H15: Timed cycles, acceptance, safe limits
... A20: D4 | B20: 2028 remobilisation and production | C20: Contractor | D20: Mar-Nov 2028 | E20: 30 | F20: D3 | G20: Explicit outages/ship calls | H20: Priority scope complete by end 2028

Sheet 11 Comparison
A1: Current Method versus Candidate Marine Access System
A3: Criterion | B3: Current scaffold methodology | C3: Candidate marine access methodology | D3: Evidence maturity | E3: Decision consequence
A4: Access establishment | B4: Full scaffold and encapsulation built/stripped at each bent, typically 3-5 days combined access handling | C4: Reusable platforms lowered, towed, lifted and recommissioned; current working allowance 11 h per move | D4: Current verified; proposed unverified trial basis | E4: Strong potential schedule improvement if supplier configuration and weather limits are proven
A5: Current demonstrated output | B5: 0.36 safe-access bent-equivalents/week; completed-bent rate not verifiable | C5: Output is scenario-based QA-closed bents/week; no demonstrated project rate yet | D5: Current claim evidence vs proposed model | E5: Do not present a direct uplift ratio
A6: Workface concurrency | B6: Four scaffold sets did not give four continuously usable fronts; up to nine bents WIP in programme | C6: Multiple access sets/pairs can be scaled; final fleet is model output | D6: Concept only | E6: Two sets are proving pair, not automatically production fleet
A7: Approval hold | B7: Approximately 3 days with scaffold standing | C7: One bent-level hold proposed after exposing both piles/headstock; repair library sensitivity | D7: Requires Jed/reviewing engineer confirmation | E7: Can materially alter fleet requirement
A8: Welding | B8: 473 lm claimed; ~52.6 lm per inspection-equivalent; 10 mm dominates | C8: Largest modelled activity; accepted lm/crew-shift and safe zones must be trialled | D8: Current quantity verified; proposed rate assumption | E8: May drive crew/fleet configuration
A9: Containment | B9: Whole bent scaffold wrap | C9: Reusable half-shell pile containment; headstock enclosure unresolved | D9: Supplier gate | E9: Major constructability and environmental gate
A10: Tide exposure | B10: Lower access and jackets tide/weather limited | C10: Platform follows work height; below-LAT jacket remains unresolved | D10: Partial | E10: Reduces but does not eliminate tidal dependence
A11: Roadway logistics | B11: Single lane used for scaffold/materials and light plant | C11: Crew/light duties by road; heavy materials, utilities and waste via JUB/water | D11: Concept | E11: Reduces congestion subject to marine logistics capacity
A12: Ship/cyclone response | B12: Make-safe and weather disruption evidenced | C12: Two-day ship make-safe, full wet-season demob and cyclone recovery to be timed | D12: Open gate | E12: Can consume calendar and fleet capacity
A13: Cost basis | B13: Current contract access basis known but remaining avoidable cost not reconciled | C13: Detailed bottom-up model prepared; total incomplete until rates/duration/fleet are closed | D13: Partial | E13: No unsupported saving claim

Sheet 12 Risks & RFIs
A1: Risk, Verification Gate and RFI Register
A3: ID | B3: Category | C3: Risk / open item | D3: Consequence | E3: Required evidence / action | F3: Owner | G3: Due | H3: Status | I3: Affects cost | J3: Affects programme | K3: Affects safety
A4: R01 | B4: Scope | C4: Priority boundary and current remaining bent/family status not confirmed | D4: Required rate, fleet, cost and method assignment remain uncertain | E4: STL issue controlled bent register | F4: STL | H4: Open | I4: Y | J4: Y | K4: N
A5: R02 | B5: Platform | C5: Selected GGC platform mass, freeboard, deck load and lifting points not confirmed | D5: Hoist and temporary-works feasibility unverified | E5: Written GGC/Hansen technical schedule | F5: GGC | H5: Open | I5: Y | J5: Y | K5: Y
A6: R03 | B6: Suspension | C6: Winch location, travelling clamp range and locking not defined | D6: Platform may not follow pile rake or survive fault cases | E6: Supplier concept + RPEQ design | F6: GGC/RPEQ | H6: Open | I6: Y | J6: Y | K6: Y
A7: R04 | B7: Traversing decks | C7: Load path between independently suspended platforms undefined | D7: 360-degree access may be unsafe/unworkable | E7: TW design and trial | F7: RPEQ/GGC | H7: Open | I7: Y | J7: Y | K7: Y
A8: R05 | B8: Containment | C8: Half-shell alignment and headstock enclosure not defined | D8: Blast/coating productivity and environmental control unproven | E8: Supplier design, airflow/noise/waste tests | F8: Supplier | H8: Open | I8: Y | J8: Y | K8: Y
A9: R06 | B9: Jackets | C9: Below-LAT installation and lower termination unresolved | D9: Bent closeout cycle incomplete | E9: Manufacturer/marine method and trial | F9: Supplier | H9: Open | I9: Y | J9: Y | K9: Y
A10: R07 | B10: Approval | C10: One bent-level three-day approval basis not confirmed | D10: Additional holds can increase cycle/fleet materially | E10: Jed and reviewing engineer decision | F10: Endura/STL | H10: Open | I10: N | J10: Y | K10: N
A11: R08 | B11: Welding | C11: Accepted lm/crew-shift and simultaneous safe weld zones unproven | D11: Largest modelled activity may be understated | E11: Timed trial incl fit-up/NDT/rework | F11: Contractor | H11: Open | I11: Y | J11: Y | K11: Y
A12: R09 | B12: Coating | C12: Active work separated from elapsed recoat holds; dated work-lot logic incomplete | D12: 14.02-day cycle is not demonstrated elapsed occupancy | E12: Manufacturer advice and proving cycle | F12: Coating supplier | H12: Open | I12: Y | J12: Y | K12: Y
A13: R10 | B13: Marine spread | C13: Bathymetry, leg penetration, JUB reach and service capacity unresolved | D13: JUB may not cover assumed workfronts or inshore area | E13: Survey + candidate JUB study | F13: STL/Marine supplier | H13: Open | I13: Y | J13: Y | K13: Y
A14: R11 | B14: Calendar | C14: Ship calls, outages, weather and wet-season blocks not fully dated | D14: Required production window can be overstated | E14: Dated calendar model | F14: STL/Planner | H14: Open | I14: Y | J14: Y | K14: Y
A15: R12 | B15: Cyclone | C15: Full fleet recovery within warning time not demonstrated | D15: Asset/environmental exposure and loss of season | E15: Timed recovery plan/drill | F15: Marine contractor | H15: Open | I15: Y | J15: Y | K15: Y
... A18: R15 | B18: Commercial | C18: GGC/JUB/labour rates and current remaining contract cost not reconciled | D18: No board-defensible cost comparison | E18: Written quotes and certified cost-to-complete | F18: Endura/STL | H18: Open | I18: Y | J18: Y | K18: N

Sheet 13 Dashboard
A1: Executive Dashboard - Current Evidence and Candidate Sensitivities
A3: Required stress rate | D3: Current safe-access claim rate | G3: Base model cycle | J3: Decision statement
A4: ='08 Productivity'!B7 | D4: ='03 Current Baseline'!E4 | G4: ='08 Productivity'!B38 | J4: Two complete access sets should be treated as a proving/leapfrog pair, not the demonstrated production fleet. Final fleet and cost require supplier data, a timed trial and the dated calendar.
A5: QA-closed bents/week | D5: stage eq/week | G5: shifts/set
A8: Base rate per set | D8: Base sets required | G8: Estimate completeness
A9: ='08 Productivity'!B39 | D9: ='08 Productivity'!B40 | G9: ='07 Cost Build Up'!H42
A10: bents/week/set | D10: diagnostic sets | G10: % numeric lines
